Workbook

Sheet README
A1: US Interfacility Transport: Sourced Evidence Master
A2: A complete, source-verified evidence base for the United States interfacility medical transport market: who moves, between which care settings, at what clinical acuity, paid by whom, at what price, and served by which suppliers. Built and verified 09 to 10 July 2026.
A4: What this workbook is, in one paragraph
A5: Every number in these 43 tabs comes from a named government dataset, a peer-reviewed study, or a published primary document, or is computed by a visible Excel formula from numbers that do. Nothing is modeled, blended, or assumed. Where a figure the market usually wants does not exist in any public source, this workbook says so and names exactly what would produce it. That refusal is deliberate: the analyses here are built to survive diligence questioning, so every claim can be walked back to its document in three steps.
A7: How to read any number in three steps
A8: Step 1: every tab tags its figures with Fact IDs (F01 to F165). Step 2: the Fact_Ledger resolves each ID to a source, tier, and locator down to the table or page. Step 3: the Source_Index identifies all 73 sources on one row each, with the full citation and URL on the Source_Register. If a figure is labeled DERIVED, the ledger names its inputs and the cell shows the arithmetic.
A10: The colour and label conventions
A11: Blue font: a value hardcoded from a source document. Black font: an Excel formula. Green font: a link to another tab. Tier A: verified against the primary document. Tier B: published but secondary, or a figure that moves over time. SOURCED: carried from an upstream dataset and not independently reopened. DERIVED: computed here, with inputs named. Every derived comparison prints its caveat in the same row it appears.
A13: The map: what each section answers
A14: Section | B14: Tabs | C14: The question it answers
A15: Governance | B15: Methodology, Findings, Charts, Verification_Log, Fact_Ledger, Source_Register, Source_Index | C15: Why every number is here, the 41 findings that matter, and the complete audit trail.
A16: Demand | B16: Demand_Drivers, Macro_Demand_Drivers, Demand_Stack, Acute_IFT_Series, Other_Transfer_Channels, Receiving_Side, EMS_Transports | C16: How many patients move, from which settings, driven by which measured forces.
A17: Medicare claims core | B17: Medicare_PSPS, Medicare_IFT_Series, Medicare_OD_Matrix, Utilization_Normalized, Acuity_by_Channel, Air_Ambulance_IFT, Dialysis_ESRD_Channel | C17: The only public origin-to-destination dollar map: volumes, dollars, acuity, and per-beneficiary rates, 2010 to 2024.
A18: Price and payment | B18: Payment_Rules, Payer_Rates_Commercial | C18: What Medicare pays and when it changes; what commercial payers and Medicaid pay, published figures only.
A19: Supply | B19: Supplier_Landscape, Supplier_Series_Raw, Supplier_Trend, Workforce_Supply, Supply_Stack | C19: Who provides transport: a decade of billing organizations, the paid and volunteer workforce, and every measured capacity constraint.
A20: Market structure | B20: State_Saturation_Raw, State_Saturation, MSA_Landscape, Imbalance_Ledger | C20: The state screen, the metro landscape, and demand-over-supply ratios including the whitespace register.
A21: Client alignment | B21: Sizing_Playbook, Engagement_Data_Map | C21: How the team converges on a defensible market number, and which source answers which question, with every awaited input named.
A22: Costs and reconciliation | B22: Cost_and_Capacity, MedPAC_2026_Mandated, Cross_Source_Recon | C22: What a transport costs to produce, and why four national sources give four different counts.
A23: Reference | B23: IFT_Alt_Measures, Code_Crosswalks, Dataset_Linkage_Map | C23: Every alternative counting route, every code system that records a transfer, and every dataset with its join keys.
A24: Integrity | B24: Fault_Audit, Data_Quality_Register, Clinical_Volumes_TierC, Excluded_Not_Sourced | C24: Every known threat to validity, and the quarantine of anything that failed the sourcing rule.
A26: What this workbook deliberately does not contain
A27: A single asserted total addressable market figure. A credible TAM requires a commercial transport volume, a Medicare Advantage transport volume, and an acuity-weighted price, and none of the three exists in any public source. A three-scenario TAM MODEL with an explicit assumption register now lives on TAM_Model_National; its outputs are scenario arithmetic under stated gates, never quoted as a single fact. The commercial and MA books are bounded here with published evidence (Payer_Rates_Commercial; the dark-share series on Imbalance_Ledger), and the exact datasets that would complete them are named on Dataset_Linkage_Map with access terms and cost.
A29: Revision summary
A30: Revision | B30: Date | C30: Contents
A31: 1 | B31: 09 July 2026 | C31: Initial evidence base: 20 tabs, facts F01 to F109, sources S01 to S38, findings 1 to 25, all verified against primary documents.
A32: 2 | B32: 10 July 2026 | C32: The complete Medicare origin-to-destination dollar map rebuilt from 392,409 raw claim rows (reconciling to the cent), the air and dialysis channels, commercial rates, macro drivers, code crosswalks, and the dataset linkage map. Facts through F135; sources through S58.
A33: 3 | B33: 10 July 2026 | C33: Per-beneficiary normalization, acuity by channel, the supplier landscape, and the payment add-on cliff. Facts through F147; sources through S61.
A34: 4 | B34: 10 July 2026 | C34: The demand and supply stacks, the imbalance ledger with the whitespace register, an eleven-year supplier series, workforce, state saturation, metro landscape, alternative counting routes, and the consolidated fault audit. Facts through F163; sources through S72.
A35: 5 | B35: 10 July 2026 | C35: Final consolidation: the official state-file cross-check (bounding the supplier-file suppression tail at 1.0%), corrections from independent external review, and full internal-consistency verification. Facts through F165; 73 sources; zero formula errors.
A37: Pending register: named enhancements, none assumed
A38: P1 HCUPnet condition-level transfer rates (point estimates; standard errors require licensed microdata under the published AHRQ variance method). P2 Ambulance-desert state and county tables. P3 Full ZCTA-to-CBSA crosswalk for complete metro coverage. P4 BLS OEWS state wage files, 2024 to 2025. P5 USRDS prevalent in-center hemodialysis counts by year. P6 NASEMSO 2020 National EMS Assessment. P7 Industry turnover and certification-pipeline measures. P8 Air-sector distress dockets. P9 SNF occupancy from the CMS Provider Information file. P10 PSPS carrier-dimension re-pull for regional origin-destination cuts, using the CMS ZIP-to-carrier-locality and rural or super-rural ZIP files. P11 Rural closure list parsed by state. P12 ECAT eCQM specifications. P13 The NHSN weekly hospital capacity series (mandated reporting resumed November 2024). P14 The CMS ZIP-to-carrier-locality and ambulance rural ZIP files themselves. P15 AHRQ Compendium hospital-to-system linkage joined to the Hospital Service Area File: the free within-system versus cross-system transfer test. P16 Completed with revision 5 (official state file, S73). P17 HCCI commercial ground brief and the Peterson-KFF out-of-network analysis. P18 The Health Affairs boarding series. P19 The published ED interfacility-transfer study and the current MedPAC Payment Basics vintage, whose organization count corroborates the supplier floor and whose transport headline, once pinned, bounds the institutional channel.
A40: Prepared with a deterministic pipeline: every dataset pull is specified to the endpoint and identifier on the Verification_Log so the entire workbook can be independently reproduced.

Sheet Methodology
A1: Why every number in this workbook is here, and why the ones that are not are not.
A2: The question here is simple: why should anyone trust this workbook? This tab is the decision record. It walks through the inclusion rule, why each evidence tab exists, the definitional choices that move the numbers, exactly how the data was pulled so it can be rerun, the rules for comparing figures, the corrections made along the way, and what the workbook still cannot do. Read this first.
A4: 1. The question this workbook answers, and the one it refuses to answer.
A5: The question. How large is US interfacility transport, who moves, between which settings, at what acuity, paid by whom, and at what price. Every tab answers one slice of that and cites the document that produced it.
A6: The refusal. This workbook does not size a total addressable market. A TAM requires a commercial-payer volume, a Medicare Advantage volume and an acuity-weighted price, none of which exists in any public source. The initial build carried three such assumptions (a 4.27x gross-up, a 2x to 4x commercial multiple, an acuity mix); all three were moved to Excluded_Not_Sourced and stayed there. revision 2 replaced two of them with published bounds rather than restoring the estimate.
A7: The consequence you must accept. Some cells on this workbook say the number does not exist. That is the finding. An analyst who needs a TAM must buy data (Dataset_Linkage_Map lists which), not blend a public one.
A9: 2. The inclusion rule, applied without exception.
A10: Rule | B10: Why | C10: What it prevents
A11: A number enters only if a named publisher document produced it, or an Excel formula computes it from numbers that did. | B11: Traceability must survive the analyst. Anyone opening a cell sees either a source-pinned constant or the arithmetic that made it. | C11: Numbers with no parent. The single most common failure in diligence workbooks is a figure that no one can source six weeks later.
A12: Blue font means hardcoded from a document. Black means a formula. Green means a link to another tab. | B12: The colour is the audit trail. A reader can see the provenance of a cell without clicking it. | C12: Hardcoded values masquerading as calculations, and stale pastes of numbers that should have updated.
A13: Every fact carries a Fact ID (F01-F147), a Tier, a Source ID and a locator down to the table or page. | B13: Tier separates what was verified against the primary document from what was asserted by an upstream workbook. | C13: Laundering. An assumption quoted twice does not become evidence.
A14: Anything labeled ILLUSTRATIVE, FRAMEWORK or INDUSTRY ESTIMATE is quarantined on Excluded_Not_Sourced. | B14: These labels are how modeled numbers enter a deck and never leave. | C14: A framework assumption being read off a chart axis as though it were measured.
A15: Derived figures are labeled DERIVED and show their inputs. | B15: A ratio of two published numbers is legitimate. A ratio of a published number and a guess is not. | C15: Same-source, same-year discipline on every multiple (see section 6).
A17: 3. Why each evidence tab exists.
A18: Tab | B18: The question it settles | C18: Why it had to be built | D18: Primary sources
A19: Acute_IFT_Series | B19: How many acute-to-acute transfers happen, from the ED and from inpatient beds. | C19: HCUP is the only national all-payer census of hospital discharges. Its two origin channels are mutually exclusive and must be added, not averaged. | D19: S01, S04
A20: Receiving_Side | B20: Does the receiving side of the ledger agree with the sending side. | C20: A transfer has two ends. NIS TRAN_IN counts arrivals independently of DISPUNIFORM departures. Agreement is the workbook internal validity test. | D20: S04
A21: EMS_Transports | B21: How many ambulance legs exist, and what share are interfacility. | C21: Hospital data counts patients moved; EMS data counts vehicles moving them. The two are different units and neither substitutes for the other. | D21: S12, S25, S55
A22: Medicare_PSPS | B22: What does Medicare fee-for-service actually pay, by acuity and by origin-destination pair. | C22: It is the only public file that carries dollars, acuity and endpoints on the same row. | D22: S13, S39
A23: Medicare_IFT_Series | B23: Is the Medicare hospital-to-hospital book growing or shrinking. | C23: No published table contains this series. It was built by pulling fifteen annual PSPS files and filtering the HH modifier. | D23: S32
A24: Medicare_OD_Matrix | B24: Where does the entire Medicare ambulance dollar go, pair by pair. | C24: revision 1 carried the HH pair only. Building the full matrix revealed that the SNF interface is 2.75x the hospital pair, which reframes the market definition. | D24: S39
A25: Utilization_Normalized | B25: Is the Medicare decline demand or denominator. | C25: FFS enrollment fell 15.5% over the same window. Without dividing by it, every trend on this workbook overstates decline by roughly a factor of two. | D25: S39, S60
A26: Acuity_by_Channel | B26: Are the interfacility channels one clinical product or several. | C26: Staffing, unit economics and payer strategy all follow acuity. SNF-to-hospital is 94% emergency; hospital-to-SNF is 99% non-emergency. One name, opposite products. | D26: S39
A27: Air_Ambulance_IFT | B27: Where does high-acuity interfacility volume actually sit. | C27: Rotary-wing is 65.6% hospital-to-hospital and grows per beneficiary while ground shrinks. Ground acuity mix cannot describe it. | D27: S40, S44
A28: Dialysis_ESRD_Channel | B28: What happens to a scheduled-transport book when a payer decides the volume is discretionary. | C28: The RSNAT rollout is a natural experiment with a date. The claims date-stamp the intervention, which makes it the template for Medicare Advantage behaviour elsewhere. | D28: S39, S41, S42
A29: Payment_Rules | B29: What governs the Medicare price, and when does it change. | C29: RVUs are frozen since 2002, geographic adjustments since 2008, and the statutory add-ons expire 1 January 2028. The price is legislative, not market. | D29: S14, S16, S28, S29, S61
... A36: Cross_Source_Recon | B36: Why do four sources give four different numbers. | C36: They measure different units on different universes. The wedge is enumerated driver by driver so the spread is explained rather than averaged away. | D36: S01, S04, S12, S13
A38: 4. Definitional choices that change the answer, and the choice this workbook made.
A39: Choice | B39: Options | C39: What was chosen and why
A40: What counts as interfacility | B40: (a) Hospital-to-hospital only. (b) Any facility-to-facility pair. (c) Any non-scene transport. | C40: (b), reported by pair. Restricting to (a) hides 2.4M SNF-interface transports; (c) sweeps in dialysis and discharge-home legs that behave nothing alike. Every tab reports pairs separately so the reader can pick.
A41: Ground base codes | B41: Six codes (A0426-A0429, A0433, A0434) or seven including paramedic intercept A0432. | C41: Six. A0432 is a rural intercept payment, not a transport (3,312 services in 2024). Stated on Acuity_by_Channel so counts tie.
A42: Service basis | B42: PSPS submitted services, or MUP-PHY final-action approved services. | C42: PSPS for all volumes and dollars; MUP only for supplier counts. The two differ by 1.10x in 2024 and must never be mixed. Data_Quality_Register #34.
A43: FFS denominator | B43: Original Medicare any part (33.9M in 2024) or Part A and B both (27.7M). | C43: A and B, the population that can generate a carrier ambulance claim. The choice moves every per-1,000 rate by about a fifth, so it is stated on the tab and in DQ #35.
A44: Fractional service counts | B44: Truncate to integers or sum as floats. | C44: Sum as floats. PSPS carries decimal service counts on shared services. The revision 1 truncation cost 39 services out of 10.6M. Correction #7.
A45: Rural closure count | B45: Sheps 154 since 2010, or Chartis 182. | C45: Sheps, with the Chartis number recorded beside it and a warning never to mix them. Different conventions on Rural Emergency Hospital conversions. DQ #31.
A46: Air interfacility inference | B46: Use O-D modifiers for both rotary and fixed-wing, or rotary only. | C46: Rotary only. Fixed-wing is 94.6% II (airport to airport), so its modifiers identify runways. DQ #29.
A48: 5. The data pipeline, stated so it can be rerun.
A49: PSPS. GET https://data.cms.gov/data-api/revision 1/dataset/{uuid}/data?filter[HCPCS_CD]={code}, paginated at 5,000 rows, one call per HCPCS per data year. Fifteen data years, twelve ambulance codes, 392,409 rows. Dataset UUIDs are printed on Verification_Log Panel F. Two schema traps: the PSPS_ field prefix begins with data year 2020 (not 2021), and service counts are decimal.
A50: MUP-PHY. Same host, filter[HCPCS_Cd]={code}, 2019 and 2024 datasets, eight base codes, 44,614 NPI-by-code rows. Rows with 10 or fewer beneficiaries are suppressed at source, so counts are floors.
A51: Enrollment. Same host, Medicare Monthly Enrollment, filter[BENE_GEO_LVL]=National and filter[MONTH]=Year, 2013 to 2025.
...

Sheet Findings
A1: What the merged evidence actually supports
A2: The question: out of everything measured here, what actually matters to a decision? These are the 41 findings, each resting on a published count or arithmetic over published counts, each with its sources, its confidence, and, most importantly, the interpretation guardrail each one carries.
A4: # | B4: Finding | C4: The numbers | D4: Sources | E4: Confidence | F4: Interpretation guardrail
A5: 1 | B5: The IFT market is roughly 3 million acute-to-acute transfer episodes a year, and that level is stable. | C5: 2,929,273 episodes in 2022. Mean of 2019 to 2023 is 3,061,156, sample standard deviation 139,226. The five-year range runs 2,929,273 (2022) to 3,234,266 (2019). | D5: S01, S04 | E5: High | F5: Never quote a single year as the level. The COVID years sit inside the band.
A6: 2 | B6: Interfacility transfer is about 9.3% of US community hospital inpatient admissions, and the level is stable at that number. | C6: 9.28% in 2022. Mean 9.49% across 2019 to 2023, band 9.24% (2021) to 9.85% (2023), sample standard deviation 0.24 points. | D6: S01, S04, S05-S11 | E6: High | F6: The number is denominator-dependent to plus or minus 0.8 points. Disclose which denominator you used.
A7: 3 | B7: The famous near-doubling of the IFT ratio is a channel mix shift, not the market exploding. | C7: The ED-origin channel went from 3.85% of admissions in 2007 to 7.33% in 2022, a 90.5% relative gain. On the COMPLETE build (ED-origin plus inpatient-origin) the same ratio grew only +1.09% per year from 2012 to 2022, and total acute-to-acute episodes grew +0.86% per year from 2012 to 2023. | D7: S01, S04, S05-S11 | E7: High | F7: Never present the 90.5% figure as market growth. It is the ED channel only.
A8: 4 | B8: Transfers migrated out of the inpatient bed and into the ED. | C8: ED-origin share of acute-to-acute episodes: 74.4% (2012), 78.9% (2022), 80.2% (2023). Inpatient-origin episodes fell at -1.48% per year while ED-origin episodes grew at +1.55% per year, 2012 to 2023. | D8: S01, S04 | E8: High | F8: This is the single clearest structural trend in the data. It is also why an ED-only measurement overstates growth.
A9: 5 | B9: IFT is counter-cyclical to hospital admissions. Volume grows while the denominator shrinks. | C9: Total acute-to-acute episodes +0.86% per year, 2012 to 2023. AHA community hospital admissions -0.67% per year over the same window. NIS discharges -0.71% per year. The complete-build ratio therefore compounds at +1.54% per year, of which 56% is numerator growth and 44% is denominator shrinkage. | D9: S01, S04, S05-S11 | E9: High | F9: The often-quoted split of four fifths numerator and one fifth denominator applies only to the ED channel over 2007 to 2022, where transfer volume compounded at +3.48% against admissions at -0.87%. Never carry it onto the complete build.
A10: 6 | B10: Carrier-billed Medicare interfacility work is low-acuity scheduled transport. It is not critical care. | C10: Of 871,753 Medicare FFS hospital-to-hospital transports in 2024: non-emergency BLS 38.8% and non-emergency ALS1 23.5%, together 62.3% of transports. Specialty Care Transport is 6.6% of transports. Weighted by actual allowed dollars, SCT is 15.6% of base-rate revenue and non-emergency BLS and ALS1 are 46.1%. The volume-weighted RVU of the book is 1.45, not 3.25. | D10: S13, S14, S28 | E10: High for carrier-billed Medicare FFS. Unknown elsewhere. | F10: Scope it carefully. PSPS is carrier claims only, so hospital-owned ambulance departments, the ones most likely to run critical-care crews, are structurally absent, and Medicare Advantage is entirely absent. It says nothing about the commercial book. What it does kill is the excluded 56.4% high-acuity assumption applied to a Medicare-weighted book. Price weighting narrows the gap between volume and revenue mix. It does not close it.
A11: 7 | B11: Interfacility is gaining share of a shrinking Medicare fee-for-service book, but the book itself peaked in 2017. | C11: Medicare FFS hospital-to-hospital transports grew from 825,178 (2022) to 871,753 (2024), +2.78% per year, while all origin-destination-coded Medicare FFS ambulance volume fell -2.80% per year. Over fifteen years, however, the interfacility book peaked at 1,139,524 transports in 2017 and is now 23.5% smaller. | D11: S13 | E11: High | F11: Read the 2022 to 2024 rate as recovery off the COVID trough, NOT as trend. The 2017 to 2024 CAGR is -3.75% per year. Medicare Advantage enrolment crossing half of all beneficiaries is the dominant driver of the fee-for-service decline, not a fall in interfacility demand.
A12: 8 | B12: Three different objects are routinely conflated, and the factor between them is 1.7 to 1.9. | C12: 2022 sending-side episodes 2,929,273. 2022 receiving-side transfer admissions 2,205,490. 2024 hospital-to-hospital ambulance transports 5,510,664. 2024 all facility-to-facility transports 7,512,656. | D12: S01, S04, S12 | E12: High | F12: This is the largest source of error in the published IFT literature, larger than sampling, coding and denominator error combined.
A13: 9 | B13: About three quarters of transfers sent arrive as an inpatient admission at a receiving acute hospital. | C13: Conversion rate 75.3% in 2022, 77.4% in 2023. The residual went to a psychiatric, rehabilitation or LTACH hospital (all outside the NIS universe), was treated and released at the receiving ED, was placed in observation, or was not coded as a transfer in. | D13: S01, S04 | E13: High | F13: The receiving-side measurement is independent: a different UB-04 field, a different hospital, a different clerk. It confirms the sending-side count.
A14: 10 | B14: Medicare fee-for-service sees only about one sixth of national interfacility transport. | C14: 871,753 Medicare FFS hospital-to-hospital transports in 2024, against 5,510,664 hospital-to-hospital transports reported by NEMSIS, or 15.8%. | D14: S12, S13 | E14: Moderate-High | F14: A floor, twice over. Hospital-owned ambulance departments bill institutionally and never enter PSPS. NEMSIS is a voluntary census and is itself a floor.
A15: 11 | B15: The government cost benchmark that circulates is a mean. The median is half of it, and that changes the conclusion. | C15: GADCS mean cost per transport is $2,673 all-in. The MEDIAN is $1,340. For-profit organizations: mean $1,788, median $610. Government: mean $3,127, median $1,859. Very-high-volume organizations: mean $946. Labor is 69.4% of the $27.2 billion aggregated cost base. Cost per RVU is $1,624 mean and $811 median, against Medicare allowed of about $253 per RVU. | D15: S30 | E15: Moderate-High | F15: The mean is dragged up by thousands of tiny low-volume organizations (mean $3,652). Quote the median for a scaled platform. The excluded market study's modeled net revenue of $1,200 to $1,400 per transport sits just below the $1,340 median, not far below a $2,673 mean. The correct statement is that the fee schedule does not cover cost and scale is the entire game.
A16: 12 | B16: Reimbursement inflation is government-set, productivity-lagged, and volatile. | C16: Verified AIF: 0.9% (2020), 0.2% (2021), 5.1% (2022), 8.7% (2023), 2.6% (2024), 2.4% (2025), 2.0% (2026). Seven-year average 3.1%, trailing three-year average 2.3%, sample standard deviation 2.9 points. Statutory add-ons of +2% urban, +3% rural and +22.6% super-rural sit on the base rate and require repeated legislative extension. | D16: S15, S16 | E16: High | F16: The source workbook carried CY2024 at 3.0%. The CMS manual and MedPAC both print 2.6%. The 8.7% in 2023 is the post-COVID CPI peak. The AIF is CPI-U less a total factor productivity adjustment, so it structurally under-runs paramedic wage inflation.
... A29: 25 | B29: The naive link between transfer delay and patient harm runs backwards, because the sickest patients move fastest. | C29: In 1,535 elderly blunt-trauma interfacility transfers, SHORTER emergency department dwell time was associated with higher injury severity, lower Glasgow Coma Scale and higher mortality. In 5,859 ED-ICU patients, ED length of stay showed no significant association with mortality after adjustment. A systematic review of 34 studies covering 2.3 million patients found variable and heterogeneous associations between ED length of stay and outcomes. | D29: S36, S37, S38 | E29: Contested. State it honestly. | F29: Never use dwell time as an outcome proxy without adjusting for acuity: the correlation has the wrong sign. The case for faster transfer rests on throughput, capacity and cost, not on a clean mortality effect. Any deck that claims boarding kills, and cites raw dwell-time correlations, is wrong on the evidence.
A30: Every single-year change under about 3% in relative terms sits inside the combined coding and sampling noise. That covers the ratio declines in 2013, 2014, 2015, 2017, 2018, 2021 and 2022.
A31: Verification. Every underlying value was checked against its primary document on 09 July 2026. 233 values checked, 228 matched exactly. Six corrections, one of which corrects an earlier claim in this workbook.
A32: Confidence is stated against the counts as AHRQ, NHTSA, CMS, RAND, MedPAC and AHA published them. What remains unverifiable is AHRQ's weighting, which is calibrated to the non-public AHA hospital-level survey.
A33: No confidence interval can be attached to any HCUP volume CAGR. AHRQ publishes no standard errors. The +0.86% per year total-episode CAGR is not demonstrably different from zero on this evidence.
A34: Peer-reviewed evidence was retrieved from PubMed on 09 July 2026 and every claim carries its digital object identifier so it can be checked at source.
A36: Findings 26 to 31, revision 2 (10 July 2026). Same rule: every one rests on a published count or arithmetic over published counts.
A37: # | B37: Finding | C37: The numbers | D37: Sources | E37: Confidence | F37: Interpretation guardrail
A38: 26 | B38: The dialysis ambulance channel collapsed by policy design, and the claims date-stamp it. | C38: Dialysis-touching O-D pairs: 2,332,855 transports (2019) to 857,750 (2024), minus 63.2%, against minus 25.6% for the whole O-D coded book. Largest single-year drop, minus 34.2%, lands in 2022, the RSNAT national rollout year. Evaluation: minus 61% use, minus 77% RSNAT spend, quality held except a 19% relative rise in emergency dialysis. | D38: S39, S41, S42 | E38: High | F38: Never read the dialysis collapse as demand loss, and do not let it contaminate the H2H trend, which GREW 2022 to 2024. It is also the template for what payer prior authorization does to any scheduled-transport book.
A39: 27 | B39: Air is the high-acuity interfacility book that ground never was. | C39: Rotary-wing Medicare transports are 65.6% hospital-to-hospital in 2024; rotary HH volume grew 34,856 to 43,683 (2010 to 2024, +25%) while ground HH fell 7%. Fixed-wing is 94.6% transfer-point-to-transfer-point: airport-coded, endpoint-blind. | D39: S40 | E39: High for Medicare FFS carrier claims | F39: Never use ground acuity mix to describe air. Never use fixed-wing O-D modifiers for anything.
A40: 28 | B40: The SNF interface, not the hospital pair, is the largest facility-to-facility channel. | C40: NH plus HN carried 2,398,253 Medicare FFS transports in 2024, 2.75 times the HH book of 871,753, and NH (SNF to hospital) is GROWING at +3.6% per year 2022 to 2024 while HN shrinks. | D40: S39, S13 | E40: High | F40: An interfacility thesis scoped to hospital-to-hospital only ignores the majority of the facility-to-facility dollar. Part A bundling (Finding 15) governs which SNF legs are separately billable.
A41: 29 | B41: Commercial pays multiples of Medicare, and the wedge is measured, not assumed. | C41: Rotary air: commercial allowed $18,668 against Medicare $3,739, same source, same year (2020): 5.0x. Ground ALS-emergency commercial allowed rose 56% in three years ($486 to $758, 2017 to 2020) while Medicare rose 4.8%. State ALS-E allowed spans $836 (IL) to $1,461 (CA) in 2022. | D41: S43, S44, S45 | E41: High within FAIR Health scope (private claim lines; excludes Medicare FFS and Medicaid) | F41: The excluded 2x to 4x assumption (Excluded_Not_Sourced #20) is retired in favor of these published bounds. Never blend payers into one rate.
A42: 30 | B42: The external ambulance-arrival anchor is now 17.0%, carries a standard error, and is frozen forever. | C42: NHAMCS 2022, the final vintage of the survey: ambulance arrival 17.0% (SE 0.9) of 155,398,000 ED visits; 33.4% at 65 and over; 39.6% at 75 and over. NEMSIS 2022 coverage of EMS-to-ED transport (17.5% of NEDS visits) sits inside the 95% interval. | D42: S55, S12, S02 | E42: High | F42: At full participation NEMSIS is not a material undercount of EMS-to-ED transport. The anchor cannot be refreshed: NHAMCS ended with 2022.
A43: 31 | B43: Coordination moves transfer volume on a measured scale, and no local coverage discretion stands in the way. | C43: Statewide transfer coordination centers were associated with an immediate 35% rise in interhospital transfer rates (RR 1.35, 95% CI 1.05 to 1.74) across 441,709 transfers in eight states. The Medicare Coverage Database holds zero active ambulance LCDs; coverage is national regulation. | D43: S54, S56 | E43: Strong, external, pandemic-period | F43: Never treat throughput as fixed: the 287-minute median delay (Finding 22) responds to coordination infrastructure. Never hunt for MAC-level ambulance coverage risk; there is none to find.
A45: Findings 32 to 35, revision 3 (10 July 2026).
A46: # | B46: Finding | C46: The numbers | D46: Sources | E46: Confidence | F46: Interpretation guardrail
A47: 32 | B47: Half the Medicare decline is the denominator, not demand. | C47: A and B fee-for-service enrollment fell 15.5% (32.8M to 27.7M, 2019 to 2024). Per 1,000 beneficiaries, the whole O-D book fell 11.9% (against 25.6% raw) and HH fell 8.0% (against 22.3% raw). The dialysis collapse survives normalization at minus 56.5%. FFS enrollment ROSE in 2025 for the first time in the series. | D47: S39, S60 | E47: High | F47: Never quote a raw PSPS trend as a demand trend. Divide by enrollment first or the comparison should be omitted.
A48: 33 | B48: Interfacility is at least three clinical products wearing one name. | C48: SNF-to-hospital is 94% emergency-coded; hospital-to-SNF is 98% BLS non-emergency; hospital-to-hospital is 62% non-emergency with SCT at 6.6%; dialysis is 96% BLS non-emergency. The HH emergency share rose 2.4 points 2019 to 2024 as payers stripped scheduled volume. | D48: S39 | E48: High | F48: No single staffing model, unit economics, or payer strategy covers the IFT book. Segment by channel and direction or the analysis is wrong on arrival.
A49: 34 | B49: The supplier base is radically fragmented and consolidating slowly. | C49: 8,721 billing NPIs in 2024 (floor; MUP suppression). Largest NPI under 1% of national services; top 10 hold 6.2%; top 100 hold 24.6% (up from 21.9% in 2019). Median NPI bills 279 Medicare transports a year. BLS non-emergency billers fell 12.7%; air billers grew. | D49: S59 | E49: High for the floor; NPI-level only | F49: Never read NPI shares as corporate shares: consolidators bill through many subsidiary NPIs, so these are floors. Corporate roll-up requires the PECOS reassignment graph.
A50: 35 | B50: Medicare ground reimbursement carries a dated statutory cliff: 1 January 2028. | C50: The 2% urban, 3% rural and 22.6% super-rural add-ons lapsed 1 October 2025, were revived through 31 January 2026, lapsed three days, and are now extended through 31 December 2027 by CAA 2026 section 6203. RVUs unchanged since 2002; geographic adjustments since 2008. | D50: S61, S28 | E50: High | F50: No revenue model on a Medicare-heavy ground book may assume the add-ons past 2027 without a scenario. Congress has extended them through lapses, not ahead of them.
A52: Findings 36 to 41, revision 4 (10 July 2026).
A53: # | B53: Finding | C53: The numbers | D53: Sources | E53: Confidence | F53: Interpretation guardrail
A54: 36 | B54: The whitespace grows by arithmetic: the unmeasurable Medicare transport market went from about a third to about three fifths in twelve years. | C54: The share of beneficiaries outside A and B fee-for-service rose from 37% (2013) to 59% (2024), computed directly from the enrollment file, with CBO pointing at 63% by 2034. Every point of migration moves transport volume from the measured book to the unmeasured one. | D54: S60, S51 | E54: Certain (arithmetic on enrollment) | F54: No public-claims trend may be presented as the market trend. The dark share travels with every chart.
A55: 37 | B55: Need per supplier is rising even as measured volume falls. | C55: Medicare beneficiaries per ground billing NPI: 6,814 (2019) to 7,797 (2024), +14.4%. The supplier base fell 6.3% over the decade (9,305 to 8,721) while beneficiaries grew; BLS non-emergency billers fell 19.4%, every year down. FFS beneficiaries per supplier fell 12.5%: the measurable window shrank faster than suppliers exited. | D55: S60, S62 | E55: High, floors throughout | F55: Never read falling FFS volume per supplier as slack; the beneficiary-based ratio is the demand-side truth.
A56: 38 | B56: Ambulance competition is metro-by-metro oligopoly inside national fragmentation. | C56: Nationally the top 10 NPIs hold 6.2% of ground volume. Within single metros the top 3 local billers routinely hold a third to two thirds (MSA_Landscape, floors). Local density, not national scale, is the competitive unit. | D56: S62 | E56: Medium: 22% of volume mapped, top-10 metro ranks robust, lower ranks not | F56: No national-share argument in a local market memo, and no metro-to-metro ratios until the full crosswalk lands.
...

Sheet Charts
A1: Charts
A2: Every series below is a live reference to the sheet that carries the data. Nothing is pasted. Change a source cell and the chart moves. Titles state what the chart is evidence for.
B4: 1. The IFT market is flat, but its share of admissions is not.
B5: Total acute-to-acute transfer episodes (bars, left axis) against IFT as a share of AHA community hospital admissions (line, right axis). The ratio rises mostly because the denominator falls. Source: Acute_IFT_Series.
B29: 2. Transfers migrated out of the inpatient bed and into the ED.
B30: ED-origin episodes (DISP_ED = 2) against inpatient-origin episodes (DISPUNIFORM = 2), 2007 to 2023. The two channels move in opposite directions. Source: Acute_IFT_Series.
B54: 3. The Medicare fee-for-service interfacility book peaked in 2017 and is a quarter smaller.
B55: Carrier-billed hospital-to-hospital ambulance transports, 2010 to 2024, rebuilt from raw CMS claims. The 2022 to 2024 recovery is a trough rebound, not trend. Source: Medicare_IFT_Series.
B79: 4. Realised Medicare rates grew below the statutory update.
B80: Allowed charges per interfacility transport and per loaded mile, 2010 to 2024. Per-transport growth is +1.90% per year against an average Ambulance Inflation Factor of 3.0% over the same window. Source: Medicare_IFT_Series.
B104: 5. Specialty Care Transport is 6.6% of the Medicare interfacility book by volume and 15.6% by revenue.
B105: Price weighting narrows the gap between volume mix and revenue mix. It does not make the book high-acuity. Source: Medicare_PSPS Panel D, 2024.
B129: 6. There is no acuity escalation, and there never was.
B130: Specialty Care Transport share of transports and the volume-weighted RVU of the whole book, 2010 to 2024. Fifteen years, essentially flat. Source: Medicare_IFT_Series.
... B201: MedPAC mean cost per transport by organisation transport-volume quartile, pooled 2022 and 2023, deflated to 2022 dollars. Average RVU per transport falls only 5% across the same range. Source: MedPAC_2026_Mandated Table 6-6.
T202: Mean cost per transport
S203: =MedPAC_2026_Mandated!A25 -> Lowest quartile of transports | T203: =MedPAC_2026_Mandated!D25 -> 2878
S204: =MedPAC_2026_Mandated!A26 -> Second quartile | T204: =MedPAC_2026_Mandated!D26 -> 1934
S205: =MedPAC_2026_Mandated!A27 -> Third quartile | T205: =MedPAC_2026_Mandated!D27 -> 1406
S206: =MedPAC_2026_Mandated!A28 -> Highest quartile | T206: =MedPAC_2026_Mandated!D28 -> 918
B223: 10. Independent community hospitals are the ones disappearing.
B224: Community hospitals in a system against independent community hospitals, AHA survey years 2018, 2023 and 2024. Independents fell 9.0% in six years. Source: Demand_Drivers Panel A.

Sheet Verification_Log
A1: Verification log
A2: The question: was every source actually opened and every extraction actually tested? This log records each verification pass, panel by panel, including the reconciliations that matched to the cent and the working hypotheses that were tested and rejected. The rejected ones stay visible on purpose: an audit trail that only records successes is not an audit trail.
A4: Panel A. Values carried in this workbook, checked against the document that published them.
A5: Evidence layer | B5: Values checked | C5: Matched exactly | D5: Corrections | E5: How it was checked | F5: Primary document opened | G5: Outcome
A6: CMS PSPS ambulance claims | B6: 60 | C6: 60 | D6: 0 | E6: Downloaded 110,568 raw claim-summary rows for 2022-2024 from the CMS data.cms.gov API and re-aggregated every origin-destination pair, every acuity HCPCS and every annual total from scratch. | F6: data.cms.gov/data-api/revision 1/dataset/{uuid}/data, Physician/Supplier Procedure Summary, 2022, 2023 and 2024 | G6: PERFECT. 12 origin-destination pairs across three years, the residual bucket, the annual totals, and all six hospital-to-hospital acuity codes across three years. Every cell matched to the unit.
A7: HCUP NEDS, DISP_ED | B7: 68 | C7: 67 | D7: 1 | E7: Downloaded 20 AHRQ weighted summary statistics PDFs (2007-2023, plus the revised 2007 and 2011 editions) and parsed the DISP_ED frequency table from each. | F7: hcup-us.ahrq.gov/db/nation/neds/stats/NEDS_{year}_MaskedStats_Core_Weighted.PDF | G7: 67 of 68 exact. The workbook correctly uses the REVISED (revision 2) editions for 2007 and 2011, where AHRQ restated transfers by up to 1.24%. The single gap is data year 2023 destination-unknown, and it is a source-mixing issue, not an error. See Cross_Source_Recon.
A8: HCUP NIS, DISPUNIFORM and TRAN_IN | B8: 74 | C8: 73 | D8: 1 | E8: Downloaded 17 AHRQ NIS weighted summary statistics PDFs and parsed DISPUNIFORM, TRAN_IN, TRAN_OUT and I10_BIRTH. | F8: hcup-us.ahrq.gov/db/nation/nis/tools/stats/ | G8: 73 of 74 exact. 2008 through 2023 is flawless. TRAN_OUT = 1 equals DISPUNIFORM = 2 in every single year, confirming it is a relabel and not independent evidence. The one gap: the 2007 NIS total omits 16,542 'discharged alive, destination unknown' records. 2007 is excluded from every trend statistic.
A9: AHA community hospital admissions | B9: 4 | C9: 4 | D9: 0 | E9: Downloaded the AHA Fast Facts PDFs and read the admissions lines directly. | F9: aha.org, Fast Facts on US Hospitals, 2025 and 2026 editions | G9: EXACT. 2023: total 34,426,650, community 32,345,846. 2024: total 35,658,583, community 33,553,725. The 2023 community figure is the denominator in the 2023 IFT ratio.
A10: NEMSIS 2024 interfacility counts | B10: 7 | C10: 7 | D10: 0 | E10: Downloaded the NEMSIS 2024 National EMS Data Report and parsed the eResponse.05 table. | F10: nemsis.org, NEMSIS End-of-Year Report 2024 | G10: EXACT. Total 60,298,684. Hospital-to-Hospital 5,510,664. Other Routine Medical Transport 4,467,204. Hospital to Non-Hospital 1,418,924. Non-Hospital to Non-Hospital 335,432. Non-Hospital to Hospital 247,636. Transports to a hospital ED 27,706,728.
A11: Ambulance Inflation Factor, CY2020-CY2025 | B11: 6 | C11: 5 | D11: 1 | E11: Read the full AIF history table in the CMS Claims Processing Manual. | F11: CMS Pub. 100-04, Ch.15 Sec.20.4, Transmittal 13464 (14 Nov 2025) | G11: CORRECTION. CY2024 is 2.6%, not the 3.0% the source market study carried. All other years match. CY2026 (2.0%) added as new.
A12: Ambulance RVUs, seven ground levels | B12: 7 | C12: 7 | D12: 0 | E12: Read the RVU table in both the CMS public use file description and the MedPAC fact sheet. | F12: CMS Ambulance Fee Schedule public use file; MedPAC Payment Basics (Ambulance), Oct 2024, Table 1 | G12: EXACT on all seven. BLS 1.00, BLS-emergency 1.60, ALS1 1.20, ALS1-emergency 1.90, paramedic intercept 1.75, ALS2 2.75, SCT 3.25. Upgraded from GOV-B to GOV-A.
A13: GADCS cost per transport | B13: 3 | C13: 2 | D13: 1 | E13: Downloaded the 201-page RAND report and read Table 6.1. | F13: RAND Corporation for CMS, GADCS Report: Year 1 and Year 2 Cohort Analysis, 19 Dec 2024 | G13: CORRECTION. Mean $2,673 and government $3,127 confirmed. Private for-profit is $1,788, NOT the $1,778 that circulates in the secondary coverage.
A14: GADCS crew labor share of cost | B14: 1 | C14: 1 | D14: 0 | E14: Read Figure 5.1 and Table 5.1. | F14: Same report | G14: CONFIRMED at 69.4%: labor is $18,869M of the $27.2B aggregated ground ambulance cost base. An earlier draft of this workbook flagged this as an unverifiable conflation. That flag was wrong and has been withdrawn.
A15: Medicare FFS ambulance spend | B15: 1 | C15: 0 | D15: 1 | E15: Read p.1 of the fact sheet, then cross-checked against the raw claims. | F15: MedPAC, Payment Basics: Ambulance Services Payment System, Oct 2024 | G15: CORRECTION. Source workbook said $4.0B for 2023. MedPAC reports $3.9B of program spending in 2022, excluding beneficiary cost sharing. Reconciled against claims: carrier-billed ground NCH payments were $3.72B in 2022; air and institutional claims close the gap.
A16: NEDS 2023 dual-table discrepancy | B16: 2 | C16: 2 | D16: 0 | E16: Downloaded the 2023 NEDS Introduction PDF (published 14 Jan 2026) and located both tables. | F16: hcup-us.ahrq.gov/db/nation/neds/NEDSIntroduction2023.pdf | G16: BOTH FIGURES CONFIRMED AS PRINTED. Table A7 reports 21,049,219 ED admissions and 2,552,895 transfers. Table D3, in the SAME document, reports 20,973,122, matching the Weighted Summary Statistics. Table A7's deltas sum to exactly zero: a reallocation, not a revision.
A17: CMS PSPS, 2010-2021 extension | B17: n/a | C17: n/a | D17: n/a | E17: Pulled every claim row carrying the HH origin-destination modifier for twelve additional data years, using the same API. Pre-2021 files drop the PSPS_ prefix on the amount fields. | F17: data.cms.gov, Physician/Supplier Procedure Summary, 2010 through 2021 | G17: NEW SERIES. No values to check: this evidence did not exist in any source workbook. Produces the fifteen-year Medicare interfacility series on Medicare_IFT_Series. The 2022-2024 overlap reproduces the verified figures exactly.
A18: MedPAC June 2026 mandated report | B18: n/a | C18: n/a | D18: n/a | E18: Downloaded the 325-page June 2026 Report to the Congress and read Chapter 6, including Tables 6-6, 6-10, 6-11 and Recommendation 6. | F18: MedPAC, Report to the Congress, June 2026, Chapter 6, published 15 June 2026 | G18: NEW SOURCE, PUBLISHED AFTER THE SOURCE WORKBOOKS. Supersedes the RAND GADCS unweighted means for operator benchmarking, quantifies the scale effect on cost, and states that GADCS-based revenue-to-cost ratios are not reliable indicators of payment adequacy today.
A19: CMS Timely and Effective Care | B19: n/a | C19: n/a | D19: n/a | E19: Queried the CMS provider-data API for the national, state and hospital files and re-derived every statistic from the returned rows (2,340 hospital records for OP-18d, 1,736 state records). | F19: data.cms.gov/provider-data, datasets isrn-hqyy, apyc-v239, yv7e-xc69 | G19: NEW SOURCE. Provides the only direct national measurement of interfacility transfer delay: OP-18d, median 287 minutes. Not present in any source workbook.
A20: AHA Fast Facts, 2020 edition | B20: n/a | C20: n/a | D20: n/a | E20: Downloaded and read the PDF for the survey-year 2018 baseline. | F20: aha.org, Fast Facts on U.S. Hospitals, 2020 edition | G20: NEW SOURCE. Community hospitals 5,198; in a system 3,491; staffed beds 792,417. Enables the 2018 to 2024 consolidation series.
A21: Peer-reviewed literature (PubMed) | B21: n/a | C21: n/a | D21: n/a | E21: Searched PubMed and retrieved article metadata and abstracts for four studies on interfacility transfer, travel time and ED boarding outcomes. | F21: PubMed. DOIs recorded on Source_Register S35 through S38. | G21: NEW SOURCE. Quantifies travel time as a transfer driver (aOR 1.32) and establishes that the naive dwell-time to mortality correlation runs backwards.
A22: TOTAL | B22: =SUM(B6:B16) -> 233 | C22: =SUM(C6:C16) -> 228 | D22: =SUM(D6:D16) -> 5 | E22: Match rate | F22: =C22/B22 -> 0.97854077 | G22: Five corrections, all applied in this file. Four are real errors in the source workbooks; the fifth is a source-mixing issue on one AHRQ cell.
A24: Panel B. The five corrections, stated plainly.
A25: # | B25: What the source workbook said | C25: What the primary document says | D25: Primary document | E25: Materiality
A26: 1 | B26: CY2024 Ambulance Inflation Factor = 3.0% | C26: CY2024 Ambulance Inflation Factor = 2.6% | D26: CMS Pub 100-04 Ch.15 Sec.20.4 | E26: Moves the trailing three-year average from 4.7% to 2.3%. Material to any rate-growth assumption.
A27: 2 | B27: Medicare FFS ambulance spend = $4.0B in 2023 | C27: $3.9B in 2022, program spending excluding beneficiary cost sharing | D27: MedPAC Payment Basics (Ambulance), Oct 2024, p.1 | E27: Wrong value and wrong year. A separate MedPAC figure of $5.3B for 2023 is TOTAL payments. Confusing the two is a 36% error.
A28: 3 | B28: GADCS private for-profit mean cost per transport = $1,778 | C28: $1,788 | D28: RAND GADCS Year 1 and Year 2 Cohort Analysis, Table 6.1 | E28: Small. But it propagated from secondary coverage into the source workbook, which is the point.
A29: 4 | B29: GADCS mean cost per transport of $2,673, quoted without its median | C29: Mean $2,673, MEDIAN $1,340 | D29: Same report, Table 6.1 | E29: Large. The mean is dragged up by thousands of tiny low-volume organizations. Quoting the mean as the operator benchmark is wrong.
A30: 5 | B30: NIS 2007 total discharges = 39,525,405 | C30: 39,541,947. The workbook omits 16,542 'destination unknown' records | D30: AHRQ NIS 2007 weighted summary statistics | E30: Immaterial. 2007 precedes the 2012 NIS redesign and is excluded from every trend statistic in this workbook.
A31: 6 | B31: This workbook claimed MedPAC's $3.9B and $5.3B ambulance spend figures 'both reconcile against the claims once air and institutional claims are added'. | C31: They do not. Carrier-billed ground plus air program payments were $4.20B in 2022, ABOVE MedPAC's $3.9B. Neither MedPAC document states the scope of its measure. | D31: CMS PSPS, air codes A0430, A0431, A0435, A0436 | E31: Material to anyone sizing the Medicare ambulance market. The claim is withdrawn and replaced with a bounded statement. See Medicare_PSPS Panel G.
A32: Panel C. Evidence obtained during verification that exists in NO source workbook.
A33: Item | B33: Value | C33: Where it came from | D33: Why it matters
A34: CY2024 ground ambulance conversion factor | B34: $272.44 | C34: MedPAC Payment Basics (Ambulance), Table 1 | D34: The source workbook ASSUMED $278.00 and labeled it ILLUSTRATIVE, which is why no dollar figure could survive.
A35: CY2024 ground mileage rate | B35: $8.76 per statute mile | C35: Same | D35: Confirmed independently by the claims: $8.79 allowed per loaded mile.
A36: Allowed charges, hospital-to-hospital base rate, 2024 | B36: $319,815,284 | C36: CMS PSPS, PSPS_ALLOWED_CHARGE_AMT | D36: Real Medicare dollars, not an RVU-times-conversion-factor estimate.
A37: Allowed charges, hospital-to-hospital mileage, 2024 | B37: $257,413,039 | C37: CMS PSPS, HCPCS A0425, modifier HH | D37: Mileage is 44.6% of the revenue on an interfacility transport.
A38: Loaded miles per hospital-to-hospital transport, 2024 | B38: 33.6 | C38: CMS PSPS | D38: Roughly three times a typical 911 scene run.
A39: Medicare payment as a share of allowed | B39: 77.7% | C39: CMS PSPS, PSPS_NCH_PAYMENT_AMT | D39: Statute sets Part B at 80% after the deductible. The realized 77.7% validates the entire extraction.
A40: GADCS median cost per transport | B40: $1,340 | C40: RAND GADCS Table 6.1 | D40: The mean of $2,673 is 1.99x the median. This changes the unit-economics conclusion.
A41: GADCS cost per RVU | B41: $1,624 mean, $811 median | C41: RAND GADCS Table 6.1 | D41: Directly comparable to the $253 per RVU that Medicare allows on the H2H book.
A42: GADCS cost composition | B42: Labor 69.4%, vehicles 10.0%, facilities 3.5% | C42: RAND GADCS Figure 5.1 and Table 5.1 | D42: Replaces the excluded trade-benchmark cost split.
...

Sheet Fact_Ledger
A1: Fact ledger
A2: The question: where does each number come from? Every fact in this workbook carries an ID here (F01 to F165) with its metric, year, value, evidence tier, source, and the exact locator inside the source document. This is step two of the three-step audit path described on the README.
A4: Fact ID | B4: Metric | C4: Year | D4: Value | E4: Unit | F4: Basis | G4: Tier | H4: Source ID | I4: Locator | J4: Lives on | K4: Cross-check
A5: F01 | B5: ED-origin acute-to-acute transfer episodes | C5: 2022 | D5: =Acute_IFT_Series!B20 -> 2311549 | E5: episodes | F5: GOV-A | G5: A | H5: S01 | I5: NEDS Summary Stats, DISP_ED = 2 | J5: Acute_IFT_Series | K5: VERIFIED against the AHRQ PDF. Agrees to the unit with NEDS Introduction 2022 Table A6
A6: F02 | B6: ED-origin acute-to-acute transfer episodes | C6: 2023 | D6: =Acute_IFT_Series!B21 -> 2554379 | E6: episodes | F6: GOV-A | G6: A | H6: S01 | I6: NEDS Summary Stats, DISP_ED = 2 | J6: Acute_IFT_Series | K6: VERIFIED. NEDS Introduction 2023 Table A7 prints 2,552,895. Gap of 1,484 (0.058%). See Cross_Source_Recon
A7: F03 | B7: Inpatient-origin acute-to-acute transfer episodes | C7: 2022 | D7: =Acute_IFT_Series!C20 -> 617724 | E7: episodes | F7: GOV-A | G7: A | H7: S04 | I7: NIS Summary Stats, DISPUNIFORM = 2 | J7: Acute_IFT_Series | K7: VERIFIED. TRAN_OUT = 1 equals this value in every year 2007-2023: a relabel, not independent evidence
A8: F04 | B8: Inpatient-origin acute-to-acute transfer episodes | C8: 2023 | D8: =Acute_IFT_Series!C21 -> 630765 | E8: episodes | F8: GOV-A | G8: A | H8: S04 | I8: NIS Summary Stats, DISPUNIFORM = 2 | J8: Acute_IFT_Series | K8: VERIFIED against the AHRQ PDF
A9: F05 | B9: Total acute-to-acute transfer episodes | C9: 2022 | D9: =Acute_IFT_Series!D20 -> 2929273 | E9: episodes | F9: DERIVED | G9: A | H9: S01, S04 | I9: Sum of F01 and F03 | J9: Acute_IFT_Series | K9: No overlap: an ED transfer-out is never also an inpatient discharge
A10: F06 | B10: Total acute-to-acute transfer episodes | C10: 2023 | D10: =Acute_IFT_Series!D21 -> 3185144 | E10: episodes | F10: DERIVED | G10: A | H10: S01, S04 | I10: Sum of F02 and F04 | J10: Acute_IFT_Series | K10: Memo year. NEDS break in series
A11: F07 | B11: Mean acute-to-acute transfer episodes, 2019 to 2023 | C11: 2023 | D11: =AVERAGE(Acute_IFT_Series!D17:D21) -> 3061155.8 | E11: episodes/yr | F11: DERIVED | G11: A | H11: S01, S04 | I11: Five-year mean | J11: Acute_IFT_Series | K11: Sample standard deviation 139,226. Range 2,929,273 (2022) to 3,234,266 (2019)
A12: F08 | B12: IFT as % of AHA community hospital admissions | C12: 2022 | D12: =Acute_IFT_Series!F20 -> 0.092828334 | E12: % | F12: DERIVED | G12: A | H12: S01, S04, S09 | I12: F05 over F18 | J12: Acute_IFT_Series | K12: Denominator choice moves this by 1.05 points. See Receiving_Side
A13: F09 | B13: IFT as % of AHA community hospital admissions | C13: 2023 | D13: =Acute_IFT_Series!F21 -> 0.098471501 | E13: % | F13: DERIVED | G13: A | H13: S01, S04, S10 | I13: F06 over 32,345,846 | J13: Acute_IFT_Series | K13: Memo year. Denominator verified in AHA Fast Facts 2025 edition
A14: F10 | B14: Mean IFT % of admissions, 2019 to 2023 | C14: 2023 | D14: =AVERAGE(Acute_IFT_Series!F17:F21) -> 0.094854988 | E14: % | F14: DERIVED | G14: A | H14: S01, S04, S06-S10 | I14: Five-year mean | J14: Acute_IFT_Series | K14: Band 9.24% (2021) to 9.85% (2023). Sample standard deviation 0.24 points
A15: F11 | B15: ED-origin share of acute-to-acute episodes | C15: 2012 | D15: =Acute_IFT_Series!G10 -> 0.74368192 | E15: % | F15: DERIVED | G15: A | H15: S01, S04 | J15: Acute_IFT_Series | K15: First comparable year after the 2012 NIS redesign
A16: F12 | B16: ED-origin share of acute-to-acute episodes | C16: 2022 | D16: =Acute_IFT_Series!G20 -> 0.78912037 | E16: % | F16: DERIVED | G16: A | H16: S01, S04 | J16: Acute_IFT_Series | K16: Rises 4.5 points over ten years
A17: F13 | B17: ED-origin share of acute-to-acute episodes | C17: 2023 | D17: =Acute_IFT_Series!G21 -> 0.80196657 | E17: % | F17: DERIVED | G17: A | H17: S01, S04 | J17: Acute_IFT_Series | K17: The clearest structural trend in the data
A18: F14 | B18: ED-origin episode CAGR, 2012 to 2023 | C18: 2023 | D18: =(Acute_IFT_Series!B21/Acute_IFT_Series!B10)^(1/11)-1 -> 0.015507851 | E18: %/yr | F18: DERIVED | G18: A | H18: S01 | I18: 11 compounding years | J18: Acute_IFT_Series | K18: 2012 is the first comparable year (NIS redesign)
A19: F15 | B19: Inpatient-origin episode CAGR, 2012 to 2023 | C19: 2023 | D19: =(Acute_IFT_Series!C21/Acute_IFT_Series!C10)^(1/11)-1 -> -0.014812798 | E19: %/yr | F19: DERIVED | G19: A | H19: S04 | J19: Acute_IFT_Series | K19: Negative. The inpatient channel is in structural decline
A20: F16 | B20: Total acute-to-acute episode CAGR, 2012 to 2023 | C20: 2023 | D20: =(Acute_IFT_Series!D21/Acute_IFT_Series!D10)^(1/11)-1 -> 0.0085659028 | E20: %/yr | F20: DERIVED | G20: A | H20: S01, S04 | J20: Acute_IFT_Series | K20: The measured market volume growth rate. NOT demonstrably different from zero: AHRQ publishes no standard errors
A21: F17 | B21: AHA community hospital admission CAGR, 2012 to 2023 | C21: 2023 | D21: =(Acute_IFT_Series!E21/Acute_IFT_Series!E10)^(1/11)-1 -> -0.0067009383 | E21: %/yr | F21: DERIVED | G21: A | H21: S05-S10 | J21: Acute_IFT_Series | K21: Negative. IFT grows as the denominator shrinks. This one is a hospital census, so it is real
A22: F18 | B22: AHA community hospital inpatient admissions | C22: 2022 | D22: =Acute_IFT_Series!E20 -> 31555807 | E22: admissions | F22: GOV-A | G22: A | H22: S09 | I22: Fast Facts, 2024 edition | J22: Acute_IFT_Series | K22: Identical in both uploaded AHA workbooks
A23: F19 | B23: AHA community hospital inpatient admissions | C23: 2024 | D23: =Cost_and_Capacity!C50 -> 33553725 | E23: admissions | F23: GOV-A | G23: A | H23: S11 | I23: Fast Facts, 2026 edition | J23: Cost_and_Capacity | K23: VERIFIED against the AHA PDF: 33,553,725. No NEDS 2024 file yet, so no 2024 ratio
A24: F20 | B24: Total admissions, all US hospitals | C24: 2024 | D24: =Cost_and_Capacity!B50 -> 35658583 | E24: admissions | F24: GOV-A | G24: A | H24: S11 | I24: Fast Facts, 2026 edition | J24: Cost_and_Capacity | K24: VERIFIED: 35,658,583. Still 1.9% below the 2018 peak of 36,353,946
A25: F21 | B25: Receiving-side transfer admissions (NIS TRAN_IN = 1) | C25: 2022 | D25: =Receiving_Side!C15 -> 2205490 | E25: admissions | F25: GOV-A | G25: A | H25: S04 | I25: NIS Summary Stats, TRAN_IN = 1 | J25: Receiving_Side | K25: VERIFIED. Derived from UB-04 Point of Origin, independent of the sending-side field
A26: F22 | B26: Receiving-side transfer admissions (NIS TRAN_IN = 1) | C26: 2023 | D26: =Receiving_Side!C16 -> 2463771 | E26: admissions | F26: GOV-A | G26: A | H26: S04 | I26: NIS Summary Stats, TRAN_IN = 1 | J26: Receiving_Side | K26: VERIFIED against the AHRQ PDF
A27: F23 | B27: Sending-to-receiving conversion rate | C27: 2022 | D27: =Receiving_Side!D15 -> 0.75291378 | E27: % | F27: DERIVED | G27: A | H27: S01, S04 | I27: F21 over F05 | J27: Receiving_Side | K27: Residual goes to psych, rehab, LTACH, ED treat-and-release, or observation
A28: F24 | B28: Sending-to-receiving conversion rate | C28: 2023 | D28: =Receiving_Side!D16 -> 0.7735195 | E28: % | F28: DERIVED | G28: A | H28: S01, S04 | J28: Receiving_Side
A29: F25 | B29: NEMSIS total EMS activations | C29: 2024 | D29: =EMS_Transports!G6 -> 60298684 | E29: activations | F29: GOV-A | G29: A | H29: S12 | I29: 2024 report, eResponse.05 table | J29: EMS_Transports | K29: VERIFIED against the NEMSIS PDF: 60,298,684. Cover box ties exactly only in 2024
A30: F26 | B30: NEMSIS Hospital-to-Hospital Transfer activations | C30: 2024 | D30: =EMS_Transports!B27 -> 5510664 | E30: transports | F30: GOV-A | G30: A | H30: S12 | I30: 2024 report, eResponse.05, v3.5 | J30: EMS_Transports | K30: VERIFIED: 5,510,664. Includes psych, rehab and LTACH destinations plus return legs. Not the HCUP definition
A31: F27 | B31: NEMSIS all facility-to-facility transfer activations | C31: 2024 | D31: =EMS_Transports!B49 -> 7512656 | E31: transports | F31: DERIVED | G31: A | H31: S12 | I31: Four v3.5 transfer categories | J31: EMS_Transports | K31: All four components verified. Excludes Other Routine Medical Transport
A32: F28 | B32: NEMSIS Other Routine Medical Transport activations | C32: 2024 | D32: =EMS_Transports!B28 -> 4467204 | E32: transports | F32: GOV-A | G32: A | H32: S12 | I32: 2024 report, eResponse.05 | J32: EMS_Transports | K32: VERIFIED: 4,467,204. Dialysis, appointments, return home. NOT interfacility transfer
A33: F29 | B33: NEMSIS Interfacility Transport activations (v3.4) | C33: 2019 | D33: =EMS_Transports!B17 -> 3309316 | E33: activations | F33: GOV-A | G33: B | H33: S12 | I33: 2019 report, eResponse.05, v3.4 | J33: EMS_Transports | K33: Coverage was 47 states. Not comparable to 2024
A34: F30 | B34: NEMSIS Interfacility Transport activations (v3.4) | C34: 2023 | D34: =EMS_Transports!F17 -> 4179580 | E34: activations | F34: GOV-A | G34: B | H34: S12 | I34: 2023 report, eResponse.05, v3.4 | J34: EMS_Transports | K34: 2023 NEMSIS denominator is understated. See Data_Quality_Register
A35: F31 | B35: NEMSIS transports to a hospital ED | C35: 2022 | D35: =EMS_Transports!E56 -> 24016095 | E35: transports | F35: GOV-A | G35: B | H35: S12 | I35: 2022 report, eDisposition.21 | J35: EMS_Transports | K35: 17.5% of NEDS weighted ED visits, against the NHAMCS anchor of 16.2%
A36: F32 | B36: NEDS weighted national ED visits | C36: 2022 | D36: =EMS_Transports!C75 -> 136974618 | E36: visits | F36: GOV-A | G36: A | H36: S02 | I36: NEDS Introduction 2022, Table 1 | J36: EMS_Transports | K36: AHA Annual Survey reports the identical figure; it is the NEDS control total
A37: F33 | B37: NEDS weighted national ED visits | C37: 2023 | D37: =EMS_Transports!C76 -> 142193558 | E37: visits | F37: GOV-A | G37: A | H37: S03 | I37: NEDS Introduction 2023, Table A6 | J37: EMS_Transports | K37: VERIFIED: 142,193,558. The nine DISP_ED categories sum to this exactly
